<?xml version="1.0" encoding="utf-8"?>
<!-- This URDF was automatically created by SolidWorks to URDF Exporter! Originally created by Stephen Brawner (brawner@gmail.com) 
     Commit Version: 1.6.0-4-g7f85cfe  Build Version: 1.6.7995.38578
     For more information, please see http://wiki.ros.org/sw_urdf_exporter -->
<robot name="sim" xmlns:xacro="http://www.ros.org/wiki/xacro">
<xacro:macro name="chassis">

    <!-- base_link -->
    <link name="base_link">
        <inertial>
            <origin xyz="-0.201 -2.8396E-05 0.096375" rpy="0 0 0" />
            <mass value="0.30883" />
            <inertia ixx="0.0010674"  ixy="-2.2706E-18" ixz="7.678E-21"
                     iyy="3.0571E-05" iyz="-1.2483E-07" izz="0.0010561" />
        </inertial>
        <visual>
            <origin xyz="-0.085 0 0.1" rpy="0 0 0" />
            <geometry>
                <box size="0.37 0.38 0.103" />
            </geometry>
            <material name="">
                <color rgba="0.1 0.1 0.1 1" />
            </material>
        </visual>
        <collision>
            <origin xyz="-0.085 0 0.1" rpy="0 0 0" />
            <geometry>
                <box size="0.37 0.38 0.103" />
            </geometry>
        </collision>
    </link>
    <gazebo reference="base_link">
        <material>Gazebo/White</material>
    </gazebo>
  
    <!-- right wheel -->
    <link name="rightwheel_Link">
        <inertial>
            <origin xyz="1.3878E-17 0.00059703 -4.3368E-19" rpy="0 0 0" />
            <mass value="0.99346" />
            <inertia ixx="0.0013174" ixy="-7.7861E-19" ixz="-5.4229E-13"
                    iyy="0.001702"  iyz="-2.2911E-20" izz="0.0013174" />
        </inertial>
        <visual>
            <origin xyz="0 0 0" rpy="1.57079637 0 0" />
            <geometry>
                <cylinder length="0.001" radius="0.061"/>
            </geometry>
            <material name="">
                <color rgba="0.5 0.5 0.5 1" />
            </material>
        </visual>
        <collision>
            <origin xyz="0 0 0" rpy="1.57079637 0 0" />
            <geometry>
                <cylinder length="0.001" radius="0.061"/>
            </geometry>
        </collision>
    </link>
    <gazebo reference="rightwheel_Link">
        <material>Gazebo/DarkGrey</material>
        <mu1>100000.0</mu1>
        <mu2>100000.0</mu2>
    </gazebo>
    <joint name="rightwheel_Joint" type="continuous">
        <origin xyz="0 -0.1239 0.061" rpy="0 0 0" />
        <parent link="base_link" />
        <child link="rightwheel_Link" />
        <axis xyz="0 1 0" />
    </joint>
    <transmission name="rightwheel_Joint_trans">
        <type>transmission_interface/SimpleTransmission</type>
        <joint name="rightwheel_Joint" >
            <hardwareInterface>hardware_interface/VelocityJointInterface</hardwareInterface>
        </joint>
        <actuator name="rightwheel_Joint_motor">
            <hardwareInterface>hardware_interface/VelocityJointInterface</hardwareInterface>
            <mechanicalReduction>1</mechanicalReduction>
        </actuator>
    </transmission>

    <!-- left wheel -->
    <link name="leftwheel_Link">
        <inertial>
            <origin xyz="1.3878E-17 -0.00059703 -1.301E-18" rpy="0 0 0" />
            <mass value="0.99346" />
            <inertia ixx="0.0013174" ixy="1.9923E-18" ixz="5.4229E-13"
                     iyy="0.001702"  iyz="5.0226E-20" izz="0.0013174" />
        </inertial>
        <visual>
            <origin xyz="0 0 0" rpy="1.57079637 0 0" />
            <geometry>
                <cylinder length="0.001" radius="0.061"/>
            </geometry>
            <material name="">
                <color rgba="0.5 0.5 0.5 1" />
            </material>
        </visual>
        <collision>
            <origin xyz="0 0 0" rpy="1.57079637 0 0" />
            <geometry>
                <cylinder length="0.001" radius="0.061"/>
            </geometry>
        </collision>
    </link>
    <gazebo reference="leftwheel_Link">
        <material>Gazebo/DarkGrey</material>
        <mu1>100000.0</mu1>
        <mu2>100000.0</mu2>
    </gazebo>
    <joint name="leftwheel_Joint" type="continuous">
        <origin xyz="0 0.1239 0.061" rpy="0 0 0" />
        <parent link="base_link" />
        <child link="leftwheel_Link" />
        <axis xyz="0 1 0" />
    </joint>
    <transmission name="leftwheel_Joint_trans">
        <type>transmission_interface/SimpleTransmission</type>
        <joint name="leftwheel_Joint" >
            <hardwareInterface>hardware_interface/VelocityJointInterface</hardwareInterface>
        </joint>
        <actuator name="leftwheel_Joint_motor">
            <hardwareInterface>hardware_interface/VelocityJointInterface</hardwareInterface>
            <mechanicalReduction>1</mechanicalReduction>
        </actuator>
    </transmission>
  
    <!-- right caster -->
    <link name="rightcaster_Link">
        <inertial>
            <origin xyz="0.112 0.17941 -0.042737" rpy="0 0 0" />
            <!-- <mass value="8.151E-13" /> -->
            <mass value="0.7" />
            <inertia ixx="5.9309E-16" ixy="-2.7931E-18" ixz="-9.8621E-18"
                     iyy="6.8504E-16" iyz="-2.994E-19"  izz="8.0561E-16" />
        </inertial>
        <visual>
            <origin xyz="0 0 -0.0716" rpy="1.57079637 0 0" />
            <geometry>
                <cylinder length="0.02" radius="0.03175"/>
            </geometry>
            <material name="">
                <color rgba="0.5 0.5 0.5 0.8" />
            </material>
        </visual>
        <collision>
            <origin xyz="0 0 -0.0716" rpy="1.57079637 0 0" />
            <geometry>
                <cylinder length="0.02" radius="0.03175"/>
            </geometry>
        </collision>
    </link>
    <gazebo reference="rightcaster_Link">
        <material>Gazebo/DarkGrey</material>
        <mu1>0.00001</mu1>
        <mu2>0.00001</mu2>
    </gazebo>
    <joint name="rightcaster_Joint" type="fixed">
        <origin xyz="-0.201 -0.112 0.1016" rpy="0 0 0" />
        <parent link="base_link" />
        <child link="rightcaster_Link" />
        <axis xyz="0 0 1" />
    </joint>
  
    <!-- left caster --> 
    <link name="leftcaster_Link">
        <inertial>
            <origin xyz="0.112 -0.044594 -0.042737" rpy="0 0 0" />
            <!-- <mass value="8.151E-13" /> -->
            <mass value="0.7" />
            <inertia ixx="5.9301E-16" ixy="-2.8584E-22" ixz="-9.8666E-18"
                     iyy="6.8512E-16" iyz="-1.1182E-22" izz="8.0561E-16" />
        </inertial>
        <visual>
            <origin xyz="0 0 -0.0716" rpy="1.57079637 0 0" />
            <geometry>
                <cylinder length="0.02" radius="0.03175"/>
            </geometry>
            <material name="">
                <color rgba="0.5 0.5 0.5 0.5" />
            </material>
        </visual>
        <collision>
            <origin xyz="0 0 -0.0716" rpy="1.57079637 0 0" />
            <geometry>
                <cylinder length="0.02" radius="0.03175"/>
            </geometry>
        </collision>
    </link>
    <gazebo reference="leftcaster_Link">
        <material>Gazebo/DarkGrey</material>
        <mu1>0.00001</mu1>
        <mu2>0.00001</mu2>
    </gazebo>
    <joint name="leftcaster_Joint" type="fixed">
        <origin xyz="-0.201 0.112 0.1016" rpy="0 0 0" />
        <parent link="base_link" />
        <child link="leftcaster_Link" />
        <axis xyz="0 0 1" />
    </joint>

    <!-- controller -->
    <gazebo>
        <plugin name="differential_drive_controller" 
            filename="libgazebo_ros_diff_drive.so">
            <rosDebugLevel>Debug</rosDebugLevel>
            <publishWheelTF>true</publishWheelTF>
            <robotNamespace>/</robotNamespace>
            <publishTf>1</publishTf>
            <publishWheelJointState>true</publishWheelJointState>
            <alwaysOn>true</alwaysOn>
            <updateRate>100.0</updateRate>
            <legacyMode>true</legacyMode>
            <leftJoint>leftwheel_Joint</leftJoint>
            <rightJoint>rightwheel_Joint</rightJoint>
            <wheelSeparation>0.2478</wheelSeparation>
            <wheelDiameter>0.122</wheelDiameter>
            <broadcastTF>1</broadcastTF>
            <wheelTorque>30</wheelTorque>
            <wheelAcceleration>1.8</wheelAcceleration>
            <commandTopic>cmd_vel</commandTopic>
            <odometryFrame>odom</odometryFrame> 
            <odometryTopic>odom</odometryTopic> 
            <robotBaseFrame>base_link</robotBaseFrame>
        </plugin>
    </gazebo> 

</xacro:macro>
</robot>
